{
    "registryname": "blastFurnace",
    "localizedname": "Blast Furnace",
    "parts": [
        {
            "x": -1,
            "y": 0,
            "z": 0,
            "elements": [
                "betternether:cincinnasite_forged"
            ]
        },
        {
            "x": 2,
            "y": 4,
            "z": 2,
            "elements": [
                "modularmachinery:blockcasing@2"
            ]
        },
        {
            "x": -2,
            "y": 0,
            "z": 0,
            "elements": [
                "betternether:cincinnasite_forged"
            ]
        },
        {
            "x": 2,
            "y": 2,
            "z": 1,
            "elements": [
                "betternether:cincinnasite_forged"
            ]
        },
        {
            "x": 1,
            "y": 0,
            "z": 0,
            "elements": [
                "betternether:cincinnasite_forged"
            ]
        },
        {
            "x": 2,
            "y": 0,
            "z": 0,
            "elements": [
                "betternether:cincinnasite_forged"
            ]
        },
        {
            "x": -2,
            "y": 0,
            "z": 4,
            "elements": [
                "betternether:cincinnasite_forged"
            ]
        },
        {
            "x": -1,
            "y": 0,
            "z": 4,
            "elements": [
                "betternether:cincinnasite_forged"
            ]
        },
        {
            "x": 0,
            "y": 0,
            "z": 4,
            "elements": [
                "modularmachinery:blockfluidinputhatch"
            ]
        },
        {
            "x": 1,
            "y": 0,
            "z": 4,
            "elements": [
                "betternether:cincinnasite_forged"
            ]
        },
        {
            "x": 2,
            "y": 0,
            "z": 4,
            "elements": [
                "betternether:cincinnasite_forged"
            ]
        },
        {
            "x": 3,
            "y": -1,
            "z": 0,
            "elements": [
                "minecraft:stone_slab"
            ]
        },
        {
            "x": -2,
            "y": 5,
            "z": 2,
            "elements": [
                "betternether:cincinnasite_forged"
            ]
        },
        {
            "x": -1,
            "y": 7,
            "z": 3,
            "elements": [
                "betternether:cincinnasite_forged"
            ]
        },
        {
            "x": -2,
            "y": 3,
            "z": 1,
            "elements": [
                "betternether:cincinnasite_forged"
            ]
        },
        {
            "x": 2,
            "y": -1,
            "z": 0,
            "elements": [
                "betternether:cincinnasite_forged"
            ]
        },
        {
            "x": 0,
            "y": 7,
            "z": 3,
            "elements": [
                "betternether:cincinnasite_forged"
            ]
        },
        {
            "x": -2,
            "y": 1,
            "z": 0,
            "elements": [
                "betternether:cincinnasite_forged"
            ]
        },
        {
            "x": 1,
            "y": 7,
            "z": 3,
            "elements": [
                "betternether:cincinnasite_forged"
            ]
        },
        {
            "x": 1,
            "y": -1,
            "z": 0,
            "elements": [
                "betternether:cincinnasite_forged"
            ]
        },
        {
            "x": 0,
            "y": -1,
            "z": 0,
            "elements": [
                "betternether:cincinnasite_forged"
            ]
        },
        {
            "x": -1,
            "y": 1,
            "z": 0,
            "elements": [
                "betternether:cincinnasite_forged"
            ]
        },
        {
            "x": 2,
            "y": 5,
            "z": 2,
            "elements": [
                "betternether:cincinnasite_forged"
            ]
        },
        {
            "x": 0,
            "y": 1,
            "z": 0,
            "elements": [
                "betternether:cincinnasite_forged"
            ]
        },
        {
            "x": -1,
            "y": -1,
            "z": 0,
            "elements": [
                "betternether:cincinnasite_forged"
            ]
        },
        {
            "x": -2,
            "y": -1,
            "z": 0,
            "elements": [
                "betternether:cincinnasite_forged"
            ]
        },
        {
            "x": 2,
            "y": 3,
            "z": 1,
            "elements": [
                "modularmachinery:blockcasing@2"
            ]
        },
        {
            "x": 1,
            "y": 1,
            "z": 0,
            "elements": [
                "betternether:cincinnasite_forged"
            ]
        },
        {
            "x": -3,
            "y": -1,
            "z": 0,
            "elements": [
                "minecraft:stone_slab"
            ]
        },
        {
            "x": -3,
            "y": -1,
            "z": 3,
            "elements": [
                "minecraft:stone_slab"
            ]
        },
        {
            "x": -2,
            "y": 1,
            "z": 4,
            "elements": [
                "betternether:cincinnasite_forged"
            ]
        },
        {
            "x": 2,
            "y": 1,
            "z": 0,
            "elements": [
                "betternether:cincinnasite_forged"
            ]
        },
        {
            "x": -2,
            "y": -1,
            "z": 3,
            "elements": [
                "betternether:cincinnasite_forged"
            ]
        },
        {
            "x": -1,
            "y": 1,
            "z": 4,
            "elements": [
                "betternether:cincinnasite_forged"
            ]
        },
        {
            "x": 0,
            "y": 1,
            "z": 4,
            "elements": [
                "trapcraft:fan@2"
            ]
        },
        {
            "x": -1,
            "y": -1,
            "z": 3,
            "elements": [
                "betternether:cincinnasite_forged"
            ]
        },
        {
            "x": 0,
            "y": -1,
            "z": 3,
            "elements": [
                "betternether:cincinnasite_forged"
            ]
        },
        {
            "x": 1,
            "y": 1,
            "z": 4,
            "elements": [
                "betternether:cincinnasite_forged"
            ]
        },
        {
            "x": 2,
            "y": 1,
            "z": 4,
            "elements": [
                "betternether:cincinnasite_forged"
            ]
        },
        {
            "x": 1,
            "y": -1,
            "z": 3,
            "elements": [
                "betternether:cincinnasite_forged"
            ]
        },
        {
            "x": 2,
            "y": -1,
            "z": 3,
            "elements": [
                "betternether:cincinnasite_forged"
            ]
        },
        {
            "x": 3,
            "y": -1,
            "z": 3,
            "elements": [
                "minecraft:stone_slab"
            ]
        },
        {
            "x": -1,
            "y": 8,
            "z": 3,
            "elements": [
                "betternether:cincinnasite_forged"
            ]
        },
        {
            "x": -2,
            "y": 4,
            "z": 1,
            "elements": [
                "betternether:cincinnasite_forged"
            ]
        },
        {
            "x": -1,
            "y": 6,
            "z": 2,
            "elements": [
                "betternether:cincinnasite_forged"
            ]
        },
        {
            "x": -2,
            "y": 2,
            "z": 0,
            "elements": [
                "betternether:cincinnasite_forged"
            ]
        },
        {
            "x": 1,
            "y": 8,
            "z": 3,
            "elements": [
                "betternether:cincinnasite_forged"
            ]
        },
        {
            "x": 1,
            "y": 6,
            "z": 2,
            "elements": [
                "betternether:cincinnasite_forged"
            ]
        },
        {
            "x": -1,
            "y": 2,
            "z": 0,
            "elements": [
                "betternether:cincinnasite_forged"
            ]
        },
        {
            "x": 0,
            "y": 2,
            "z": 0,
            "elements": [
                "betternether:cincinnasite_forged"
            ]
        },
        {
            "x": 2,
            "y": 4,
            "z": 1,
            "elements": [
                "modularmachinery:blockcasing@2"
            ]
        },
        {
            "x": 1,
            "y": 2,
            "z": 0,
            "elements": [
                "betternether:cincinnasite_forged"
            ]
        },
        {
            "x": -2,
            "y": 2,
            "z": 4,
            "elements": [
                "betternether:cincinnasite_forged"
            ]
        },
        {
            "x": 2,
            "y": 2,
            "z": 0,
            "elements": [
                "betternether:cincinnasite_forged"
            ]
        },
        {
            "x": -2,
            "y": 0,
            "z": 3,
            "elements": [
                "betternether:cincinnasite_forged"
            ]
        },
        {
            "x": -1,
            "y": 2,
            "z": 4,
            "elements": [
                "betternether:cincinnasite_forged"
            ]
        },
        {
            "x": 0,
            "y": 2,
            "z": 4,
            "elements": [
                "betternether:cincinnasite_forged"
            ]
        },
        {
            "x": 1,
            "y": 2,
            "z": 4,
            "elements": [
                "betternether:cincinnasite_forged"
            ]
        },
        {
            "x": 2,
            "y": 2,
            "z": 4,
            "elements": [
                "betternether:cincinnasite_forged"
            ]
        },
        {
            "x": 2,
            "y": 0,
            "z": 3,
            "elements": [
                "betternether:cincinnasite_forged"
            ]
        },
        {
            "x": -1,
            "y": 9,
            "z": 3,
            "elements": [
                "betternether:cincinnasite_forged"
            ]
        },
        {
            "x": 0,
            "y": 9,
            "z": 3,
            "elements": [
                "betternether:cincinnasite_forged"
            ]
        },
        {
            "x": -2,
            "y": 5,
            "z": 1,
            "elements": [
                "betternether:cincinnasite_forged"
            ]
        },
        {
            "x": -1,
            "y": 7,
            "z": 2,
            "elements": [
                "betternether:cincinnasite_forged"
            ]
        },
        {
            "x": -2,
            "y": 3,
            "z": 0,
            "elements": [
                "betternether:cincinnasite_forged"
            ]
        },
        {
            "x": 1,
            "y": 9,
            "z": 3,
            "elements": [
                "betternether:cincinnasite_forged"
            ]
        },
        {
            "x": -1,
            "y": 3,
            "z": 0,
            "elements": [
                "betternether:cincinnasite_forged"
            ]
        },
        {
            "x": 1,
            "y": 7,
            "z": 2,
            "elements": [
                "betternether:cincinnasite_forged"
            ]
        },
        {
            "x": 0,
            "y": 3,
            "z": 0,
            "elements": [
                "betternether:cincinnasite_forged"
            ]
        },
        {
            "x": 2,
            "y": 5,
            "z": 1,
            "elements": [
                "betternether:cincinnasite_forged"
            ]
        },
        {
            "x": 1,
            "y": 3,
            "z": 0,
            "elements": [
                "betternether:cincinnasite_forged"
            ]
        },
        {
            "x": -2,
            "y": 3,
            "z": 4,
            "elements": [
                "betternether:cincinnasite_forged"
            ]
        },
        {
            "x": 2,
            "y": 3,
            "z": 0,
            "elements": [
                "betternether:cincinnasite_forged"
            ]
        },
        {
            "x": -3,
            "y": -1,
            "z": 2,
            "elements": [
                "minecraft:stone_slab"
            ]
        },
        {
            "x": -2,
            "y": 1,
            "z": 3,
            "elements": [
                "betternether:cincinnasite_forged"
            ]
        },
        {
            "x": -1,
            "y": 3,
            "z": 4,
            "elements": [
                "betternether:cincinnasite_forged"
            ]
        },
        {
            "x": 0,
            "y": 3,
            "z": 4,
            "elements": [
                "betternether:cincinnasite_forged"
            ]
        },
        {
            "x": -2,
            "y": -1,
            "z": 2,
            "elements": [
                "betternether:cincinnasite_forged"
            ]
        },
        {
            "x": 1,
            "y": 3,
            "z": 4,
            "elements": [
                "betternether:cincinnasite_forged"
            ]
        },
        {
            "x": -1,
            "y": -1,
            "z": 2,
            "elements": [
                "betternether:cincinnasite_forged"
            ]
        },
        {
            "x": 0,
            "y": -1,
            "z": 2,
            "elements": [
                "betternether:cincinnasite_forged"
            ]
        },
        {
            "x": 2,
            "y": 3,
            "z": 4,
            "elements": [
                "betternether:cincinnasite_forged"
            ]
        },
        {
            "x": 2,
            "y": 1,
            "z": 3,
            "elements": [
                "betternether:cincinnasite_forged"
            ]
        },
        {
            "x": 1,
            "y": -1,
            "z": 2,
            "elements": [
                "betternether:cincinnasite_forged"
            ]
        },
        {
            "x": 2,
            "y": -1,
            "z": 2,
            "elements": [
                "betternether:cincinnasite_forged"
            ]
        },
        {
            "x": 3,
            "y": -1,
            "z": 2,
            "elements": [
                "minecraft:stone_slab"
            ]
        },
        {
            "x": -1,
            "y": 8,
            "z": 2,
            "elements": [
                "betternether:cincinnasite_forged"
            ]
        },
        {
            "x": -2,
            "y": 4,
            "z": 0,
            "elements": [
                "betternether:cincinnasite_forged"
            ]
        },
        {
            "x": -1,
            "y": 6,
            "z": 1,
            "elements": [
                "betternether:cincinnasite_forged"
            ]
        },
        {
            "x": 0,
            "y": 8,
            "z": 2,
            "elements": [
                "modularmachinery:blockinputbus"
            ]
        },
        {
            "x": -1,
            "y": 4,
            "z": 0,
            "elements": [
                "betternether:cincinnasite_forged"
            ]
        },
        {
            "x": 1,
            "y": 8,
            "z": 2,
            "elements": [
                "betternether:cincinnasite_forged"
            ]
        },
        {
            "x": 0,
            "y": 6,
            "z": 1,
            "elements": [
                "betternether:cincinnasite_forged"
            ]
        },
        {
            "x": 1,
            "y": 6,
            "z": 1,
            "elements": [
                "betternether:cincinnasite_forged"
            ]
        },
        {
            "x": 0,
            "y": 4,
            "z": 0,
            "elements": [
                "betternether:cincinnasite_forged"
            ]
        },
        {
            "x": 1,
            "y": 4,
            "z": 0,
            "elements": [
                "betternether:cincinnasite_forged"
            ]
        },
        {
            "x": -2,
            "y": 4,
            "z": 4,
            "elements": [
                "betternether:cincinnasite_forged"
            ]
        },
        {
            "x": 2,
            "y": 4,
            "z": 0,
            "elements": [
                "betternether:cincinnasite_forged"
            ]
        },
        {
            "x": -2,
            "y": 2,
            "z": 3,
            "elements": [
                "betternether:cincinnasite_forged"
            ]
        },
        {
            "x": -1,
            "y": 4,
            "z": 4,
            "elements": [
                "betternether:cincinnasite_forged"
            ]
        },
        {
            "x": 0,
            "y": 4,
            "z": 4,
            "elements": [
                "betternether:cincinnasite_forged"
            ]
        },
        {
            "x": -2,
            "y": 0,
            "z": 2,
            "elements": [
                "modularmachinery:blockoutputbus"
            ]
        },
        {
            "x": 1,
            "y": 4,
            "z": 4,
            "elements": [
                "betternether:cincinnasite_forged"
            ]
        },
        {
            "x": 2,
            "y": 4,
            "z": 4,
            "elements": [
                "betternether:cincinnasite_forged"
            ]
        },
        {
            "x": 2,
            "y": 2,
            "z": 3,
            "elements": [
                "betternether:cincinnasite_forged"
            ]
        },
        {
            "x": 2,
            "y": 0,
            "z": 2,
            "elements": [
                "modularmachinery:blockenergyinputhatch"
            ]
        },
        {
            "x": -1,
            "y": 9,
            "z": 2,
            "elements": [
                "betternether:cincinnasite_forged"
            ]
        },
        {
            "x": 0,
            "y": 9,
            "z": 2,
            "elements": [
                "minecraft:hopper@0"
            ]
        },
        {
            "x": -2,
            "y": 5,
            "z": 0,
            "elements": [
                "betternether:cincinnasite_forged"
            ]
        },
        {
            "x": -1,
            "y": 7,
            "z": 1,
            "elements": [
                "betternether:cincinnasite_forged"
            ]
        },
        {
            "x": -1,
            "y": 5,
            "z": 0,
            "elements": [
                "betternether:cincinnasite_forged"
            ]
        },
        {
            "x": 1,
            "y": 9,
            "z": 2,
            "elements": [
                "betternether:cincinnasite_forged"
            ]
        },
        {
            "x": 0,
            "y": 7,
            "z": 1,
            "elements": [
                "betternether:cincinnasite_forged"
            ]
        },
        {
            "x": 1,
            "y": 7,
            "z": 1,
            "elements": [
                "betternether:cincinnasite_forged"
            ]
        },
        {
            "x": 0,
            "y": 5,
            "z": 0,
            "elements": [
                "betternether:cincinnasite_forged"
            ]
        },
        {
            "x": 1,
            "y": 5,
            "z": 0,
            "elements": [
                "betternether:cincinnasite_forged"
            ]
        },
        {
            "x": 2,
            "y": 5,
            "z": 0,
            "elements": [
                "betternether:cincinnasite_forged"
            ]
        },
        {
            "x": -2,
            "y": 5,
            "z": 4,
            "elements": [
                "betternether:cincinnasite_forged"
            ]
        },
        {
            "x": -2,
            "y": 3,
            "z": 3,
            "elements": [
                "betternether:cincinnasite_forged"
            ]
        },
        {
            "x": -1,
            "y": 5,
            "z": 4,
            "elements": [
                "betternether:cincinnasite_forged"
            ]
        },
        {
            "x": -3,
            "y": -1,
            "z": 1,
            "elements": [
                "minecraft:stone_slab"
            ]
        },
        {
            "x": -2,
            "y": 1,
            "z": 2,
            "elements": [
                "betternether:cincinnasite_forged"
            ]
        },
        {
            "x": 0,
            "y": 5,
            "z": 4,
            "elements": [
                "betternether:cincinnasite_forged"
            ]
        },
        {
            "x": 1,
            "y": 5,
            "z": 4,
            "elements": [
                "betternether:cincinnasite_forged"
            ]
        },
        {
            "x": -2,
            "y": -1,
            "z": 1,
            "elements": [
                "betternether:cincinnasite_forged"
            ]
        },
        {
            "x": 2,
            "y": 5,
            "z": 4,
            "elements": [
                "betternether:cincinnasite_forged"
            ]
        },
        {
            "x": -1,
            "y": -1,
            "z": 1,
            "elements": [
                "betternether:cincinnasite_forged"
            ]
        },
        {
            "x": 0,
            "y": -1,
            "z": 1,
            "elements": [
                "betternether:cincinnasite_forged"
            ]
        },
        {
            "x": 2,
            "y": 3,
            "z": 3,
            "elements": [
                "modularmachinery:blockcasing@2"
            ]
        },
        {
            "x": -3,
            "y": -1,
            "z": 5,
            "elements": [
                "minecraft:stone_slab"
            ]
        },
        {
            "x": 2,
            "y": 1,
            "z": 2,
            "elements": [
                "betternether:cincinnasite_forged"
            ]
        },
        {
            "x": 1,
            "y": -1,
            "z": 1,
            "elements": [
                "betternether:cincinnasite_forged"
            ]
        },
        {
            "x": 2,
            "y": -1,
            "z": 1,
            "elements": [
                "betternether:cincinnasite_forged"
            ]
        },
        {
            "x": -2,
            "y": -1,
            "z": 5,
            "elements": [
                "minecraft:stone_slab"
            ]
        },
        {
            "x": 3,
            "y": -1,
            "z": 1,
            "elements": [
                "minecraft:stone_slab"
            ]
        },
        {
            "x": -1,
            "y": -1,
            "z": 5,
            "elements": [
                "minecraft:stone_slab"
            ]
        },
        {
            "x": 0,
            "y": -1,
            "z": 5,
            "elements": [
                "minecraft:stone_slab"
            ]
        },
        {
            "x": 1,
            "y": -1,
            "z": 5,
            "elements": [
                "minecraft:stone_slab"
            ]
        },
        {
            "x": 2,
            "y": -1,
            "z": 5,
            "elements": [
                "minecraft:stone_slab"
            ]
        },
        {
            "x": 3,
            "y": -1,
            "z": 5,
            "elements": [
                "minecraft:stone_slab"
            ]
        },
        {
            "x": -1,
            "y": 8,
            "z": 1,
            "elements": [
                "betternether:cincinnasite_forged"
            ]
        },
        {
            "x": 0,
            "y": 8,
            "z": 1,
            "elements": [
                "betternether:cincinnasite_forged"
            ]
        },
        {
            "x": 1,
            "y": 8,
            "z": 1,
            "elements": [
                "betternether:cincinnasite_forged"
            ]
        },
        {
            "x": -2,
            "y": 4,
            "z": 3,
            "elements": [
                "betternether:cincinnasite_forged"
            ]
        },
        {
            "x": -2,
            "y": 2,
            "z": 2,
            "elements": [
                "betternether:cincinnasite_forged"
            ]
        },
        {
            "x": -2,
            "y": 0,
            "z": 1,
            "elements": [
                "betternether:cincinnasite_forged"
            ]
        },
        {
            "x": 2,
            "y": 4,
            "z": 3,
            "elements": [
                "modularmachinery:blockcasing@2"
            ]
        },
        {
            "x": 2,
            "y": 2,
            "z": 2,
            "elements": [
                "betternether:cincinnasite_forged"
            ]
        },
        {
            "x": 2,
            "y": 0,
            "z": 1,
            "elements": [
                "betternether:cincinnasite_forged"
            ]
        },
        {
            "x": -1,
            "y": 9,
            "z": 1,
            "elements": [
                "betternether:cincinnasite_forged"
            ]
        },
        {
            "x": 0,
            "y": 9,
            "z": 1,
            "elements": [
                "betternether:cincinnasite_forged"
            ]
        },
        {
            "x": 1,
            "y": 9,
            "z": 1,
            "elements": [
                "betternether:cincinnasite_forged"
            ]
        },
        {
            "x": 3,
            "y": -1,
            "z": -1,
            "elements": [
                "minecraft:stone_slab"
            ]
        },
        {
            "x": -2,
            "y": 5,
            "z": 3,
            "elements": [
                "betternether:cincinnasite_forged"
            ]
        },
        {
            "x": -2,
            "y": 3,
            "z": 2,
            "elements": [
                "betternether:cincinnasite_forged"
            ]
        },
        {
            "x": 2,
            "y": -1,
            "z": -1,
            "elements": [
                "minecraft:stone_slab"
            ]
        },
        {
            "x": -2,
            "y": 1,
            "z": 1,
            "elements": [
                "betternether:cincinnasite_forged"
            ]
        },
        {
            "x": 1,
            "y": -1,
            "z": -1,
            "elements": [
                "minecraft:stone_slab"
            ]
        },
        {
            "x": 0,
            "y": -1,
            "z": -1,
            "elements": [
                "minecraft:stone_slab"
            ]
        },
        {
            "x": 2,
            "y": 5,
            "z": 3,
            "elements": [
                "betternether:cincinnasite_forged"
            ]
        },
        {
            "x": -1,
            "y": -1,
            "z": -1,
            "elements": [
                "minecraft:stone_slab"
            ]
        },
        {
            "x": -2,
            "y": -1,
            "z": -1,
            "elements": [
                "minecraft:stone_slab"
            ]
        },
        {
            "x": 2,
            "y": 3,
            "z": 2,
            "elements": [
                "modularmachinery:blockcasing@2"
            ]
        },
        {
            "x": -3,
            "y": -1,
            "z": -1,
            "elements": [
                "minecraft:stone_slab"
            ]
        },
        {
            "x": -3,
            "y": -1,
            "z": 4,
            "elements": [
                "minecraft:stone_slab"
            ]
        },
        {
            "x": 2,
            "y": 1,
            "z": 1,
            "elements": [
                "betternether:cincinnasite_forged"
            ]
        },
        {
            "x": -2,
            "y": -1,
            "z": 4,
            "elements": [
                "betternether:cincinnasite_forged"
            ]
        },
        {
            "x": -1,
            "y": -1,
            "z": 4,
            "elements": [
                "betternether:cincinnasite_forged"
            ]
        },
        {
            "x": 0,
            "y": -1,
            "z": 4,
            "elements": [
                "betternether:cincinnasite_forged"
            ]
        },
        {
            "x": 1,
            "y": -1,
            "z": 4,
            "elements": [
                "betternether:cincinnasite_forged"
            ]
        },
        {
            "x": 2,
            "y": -1,
            "z": 4,
            "elements": [
                "betternether:cincinnasite_forged"
            ]
        },
        {
            "x": 3,
            "y": -1,
            "z": 4,
            "elements": [
                "minecraft:stone_slab"
            ]
        },
        {
            "x": -2,
            "y": 4,
            "z": 2,
            "elements": [
                "betternether:cincinnasite_forged"
            ]
        },
        {
            "x": -1,
            "y": 6,
            "z": 3,
            "elements": [
                "betternether:cincinnasite_forged"
            ]
        },
        {
            "x": -2,
            "y": 2,
            "z": 1,
            "elements": [
                "betternether:cincinnasite_forged"
            ]
        },
        {
            "x": 0,
            "y": 6,
            "z": 3,
            "elements": [
                "betternether:cincinnasite_forged"
            ]
        },
        {
            "x": 1,
            "y": 6,
            "z": 3,
            "elements": [
                "betternether:cincinnasite_forged"
            ]
        }
    ]}