
# Created by Ruins mod version 17.2 Ingame Parser
# authoring Player: CN_Eicy

# TEMPLATE PARAMETER SETTINGS:
#
# criterion expression specifying mod ids required to load template
# may include plus (AND), minus (AND NOT), comma (OR), and parentheses
# all required mods listed must be present; no prohibited mods can be
requiredMods=
#
# likelihood this template will be chosen relative to all others
# e.g., a weight=6 template is chosen 3X as often as one with weight=2
weight=1
#
# list of dimensions in which this template may spawn, even if generic
# one or more dimension names, separated by commas (blank = all)
dimensionsToSpawnIn=
#
# list of other biomes in which this template may spawn
# biome corresponding to directory is always assumed, listed or not
# generic templates should leave this list empty
biomesToSpawnIn=
#
# criterion expression specifying types of biome where template spawns
# this is in addition to those explicitly listed as biomesToSpawnIn
# generic templates should leave this list empty
biomeTypesToSpawnIn=
#
# list of biomes in which this template may not spawn
# takes precedence over biomeTypesToSpawnIn, but NOT biomesToSpawnIn
# should be empty if biomeTypesToSpawnIn is empty
biomesToNotSpawnIn=
#
# depth template is pushed down into the surface when built
# offset is min/max range of random additional bury depth
embed_into_distance=0
random_height_offset=0,0
#
# whitelist/blacklist of block types on which template may be built
# specify one, not both; leave the other empty (both empty = allow all)
acceptable_target_blocks=
unacceptable_target_blocks=flowing_water,water,flowing_lava,lava
#
# size of template (#layers, #rows per layer, #blocks per row)
dimensions=22,12,13
#
# max number of missing blocks allowed in surface beneath template
allowable_overhang=0
#
# depth/height limit affected by terrain leveling
# also maximum bumpiness tolerated in surface beneath template
max_leveling=2
#
# padding applied to all sides of template horizontal footprint
# expands area affected by terrain leveling (-1 = no leveling)
leveling_buffer=0
#
# do not rotate template randomly when built (1 = no rotation)
preventRotation=0
#
# treat water/lava blocks as air and protect them from rule0 (1 = yes)
preserve_water=0
preserve_lava=0
#
# minimum distance this template must have from instances of itself
uniqueMinDistance=0
#
# min/max distances this template can be from world spawn (0 = no limit)
# only applies to overworld--i.e., dimension 0
spawnMinDistance=0
spawnMaxDistance=0
#
# other template built nearby whenever this one is
# syntax: <name>;<relativeX>;<maxYdifference>;<relativeZ>[;<chance>]
# may be used more than once to specify multiple neighbors
adjoining_template=

rule1=0,100,minecraft:netherrack-0
rule2=0,100,betternether:cincinnasite_ore-0
rule3=0,100,minecraft:planks-0
rule4=0,100,minecraft:wooden_door-6
rule5=0,100,minecraft:wooden_slab-0
rule6=0,100,minecraft:wooden_slab-8
rule7=2,100,minecraft:torch-2
rule8=0,100,minecraft:wooden_door-9
rule9=2,100,minecraft:torch-3
rule10=0,100,minecraft:glass_pane-0
rule11=2,100,minecraft:torch-4
rule12=0,100,minecraft:stained_hardened_clay-1
rule13=0,100,dungeonmobs:bladetrap-0
rule14=0,100,minecraft:bookshelf-0
rule15=0,100,IInventory;ebwizardry:arcane_workbench;minecraft:air#0#0#0+minecraft:air#0#0#1+minecraft:air#0#0#2+minecraft:air#0#0#3+minecraft:air#0#0#4+minecraft:air#0#0#5+minecraft:air#0#0#6+minecraft:air#0#0#7+minecraft:air#0#0#8+minecraft:air#0#0#9+minecraft:air#0#0#10-0
rule16=0,100,IInventory;minecraft:chest;hammercore:emerald_bordered_cobblestone#1#0#0-3

layer
0,0,0,0,0,0,0,0,0,0,0,0,0
0,0,0,0,0,0,0,0,0,0,0,0,0
0,0,0,0,0,0,0,0,0,0,0,0,0
0,0,0,0,0,0,0,0,0,0,0,0,0
0,0,0,0,1,2,1,0,0,0,0,0,0
0,0,0,1,3,3,3,2,0,0,0,0,0
0,0,0,1,3,3,3,1,0,0,0,0,0
0,0,0,2,3,3,3,1,0,0,0,0,0
0,0,0,0,1,1,2,0,0,0,0,0,0
0,0,0,0,0,0,0,0,0,0,0,0,0
0,0,0,0,0,0,0,0,0,0,0,0,0
0,0,0,0,0,0,0,0,0,0,0,0,0
endlayer

layer
0,0,0,0,0,0,0,0,0,0,0,0,0
0,0,0,0,0,0,0,0,0,0,0,0,0
0,0,0,0,0,0,0,0,0,0,0,0,0
0,0,0,0,0,0,0,0,0,0,0,0,0
0,0,0,0,1,4,1,0,0,0,0,0,0
0,0,0,1,0,0,0,1,0,0,0,0,0
0,0,0,1,0,0,0,1,0,0,0,0,0
0,0,0,1,0,6,5,2,0,0,0,0,0
0,0,0,0,1,1,1,0,0,0,0,0,0
0,0,0,0,0,0,0,0,0,0,0,0,0
0,0,0,0,0,0,0,0,0,0,0,0,0
0,0,0,0,0,0,0,0,0,0,0,0,0
endlayer

layer
0,0,0,0,0,0,0,0,0,0,0,0,0
0,0,0,0,0,0,0,0,0,0,0,0,0
0,0,0,0,0,0,0,0,0,0,0,0,0
0,0,0,0,7,0,7,0,0,0,0,0,0
0,0,0,0,1,8,1,0,0,0,0,0,0
0,0,0,1,0,0,0,1,0,0,0,0,0
0,0,0,1,6,0,0,1,0,0,0,0,0
0,0,0,1,5,0,0,1,0,0,0,0,0
0,0,0,0,1,1,1,0,0,0,0,0,0
0,0,0,0,0,0,0,0,0,0,0,0,0
0,0,0,0,0,0,0,0,0,0,0,0,0
0,0,0,0,0,0,0,0,0,0,0,0,0
endlayer

layer
0,0,0,0,0,0,0,0,0,0,0,0,0
0,0,0,0,0,0,0,0,0,0,0,0,0
0,0,0,0,0,0,0,0,0,0,0,0,0
0,0,0,0,0,0,0,0,0,0,0,0,0
0,0,0,0,1,1,1,0,0,0,0,0,0
0,0,0,1,5,6,0,1,0,0,0,0,0
0,0,0,1,0,0,9,1,0,0,0,0,0
0,0,0,1,0,0,0,1,0,0,0,0,0
0,0,0,0,1,10,1,0,0,0,0,0,0
0,0,0,0,0,0,0,0,0,0,0,0,0
0,0,0,0,0,0,0,0,0,0,0,0,0
0,0,0,0,0,0,0,0,0,0,0,0,0
endlayer

layer
0,0,0,0,0,0,0,0,0,0,0,0,0
0,0,0,0,0,0,0,0,0,0,0,0,0
0,0,0,0,0,0,0,0,0,0,0,0,0
0,0,0,0,0,0,0,0,0,0,0,0,0
0,0,0,0,1,1,1,0,0,0,0,0,0
0,0,0,1,0,0,5,1,0,0,0,0,0
0,0,0,1,0,0,6,1,1,1,0,0,0
0,0,0,1,0,0,0,1,0,0,0,0,0
0,0,0,0,1,1,1,0,0,0,0,0,0
0,0,0,0,0,0,0,0,0,0,0,0,0
0,0,0,0,0,0,0,0,0,0,0,0,0
0,0,0,0,0,0,0,0,0,0,0,0,0
endlayer

layer
0,0,0,0,0,0,0,0,0,0,0,0,0
0,0,0,0,0,0,0,0,0,0,0,0,0
0,0,0,0,0,0,0,0,0,0,0,0,0
0,0,0,0,0,0,0,0,0,0,0,0,0
0,0,0,0,1,10,1,0,0,0,0,0,0
0,0,0,1,0,0,0,1,1,1,0,0,0
0,0,0,1,11,0,0,0,0,0,1,0,0
0,0,0,1,0,6,5,1,1,1,0,0,0
0,0,0,0,1,1,1,0,0,0,0,0,0
0,0,0,0,0,0,0,0,0,0,0,0,0
0,0,0,0,0,0,0,0,0,0,0,0,0
0,0,0,0,0,0,0,0,0,0,0,0,0
endlayer

layer
0,0,0,0,0,0,0,0,0,0,0,0,0
0,0,0,0,0,0,0,0,0,0,0,0,0
0,0,0,0,0,0,0,0,0,0,0,0,0
0,0,0,0,0,0,0,0,0,0,0,0,0
0,0,0,0,1,1,1,0,0,0,0,0,0
0,0,0,1,0,0,0,1,1,10,1,0,0
0,0,0,1,6,0,0,0,0,0,10,0,0
0,0,0,1,5,0,0,1,1,10,1,0,0
0,0,0,0,1,1,1,0,0,0,0,0,0
0,0,0,0,0,0,0,0,0,0,0,0,0
0,0,0,0,0,0,0,0,0,0,0,0,0
0,0,0,0,0,0,0,0,0,0,0,0,0
endlayer

layer
0,0,0,0,0,0,0,0,0,0,0,0,0
0,0,0,0,0,0,0,0,0,0,0,0,0
0,0,0,0,0,0,0,0,0,0,0,0,0
0,0,0,0,0,0,0,0,0,0,0,0,0
0,0,0,0,1,1,1,0,12,12,12,0,0
0,0,0,1,5,6,0,1,1,1,1,12,0
0,0,0,1,0,0,9,1,0,0,1,12,0
0,0,0,1,0,0,0,1,1,1,1,12,0
0,0,0,0,1,10,1,0,12,12,12,0,0
0,0,0,0,0,0,0,0,0,0,0,0,0
0,0,0,0,0,0,0,0,0,0,0,0,0
0,0,0,0,0,0,0,0,0,0,0,0,0
endlayer

layer
0,0,0,0,0,0,0,0,0,0,0,0,0
0,0,0,0,0,0,0,0,0,0,0,0,0
0,0,0,0,0,0,0,0,0,0,0,0,0
0,0,0,0,0,0,0,0,0,0,0,0,0
0,0,0,0,1,1,1,0,0,0,0,0,0
0,0,0,1,0,0,5,1,12,12,12,0,0
0,0,0,1,0,0,6,1,12,0,12,0,0
0,0,0,1,0,0,0,1,12,12,12,0,0
0,0,0,0,1,1,1,0,0,0,0,0,0
0,0,0,0,0,0,0,0,0,0,0,0,0
0,0,0,0,0,0,0,0,0,0,0,0,0
0,0,0,0,0,0,0,0,0,0,0,0,0
endlayer

layer
0,0,0,0,0,0,0,0,0,0,0,0,0
0,0,0,0,0,0,0,0,0,0,0,0,0
0,0,0,0,0,0,0,0,0,0,0,0,0
0,0,0,0,0,0,0,0,0,0,0,0,0
0,0,0,0,1,10,1,0,0,0,0,0,0
0,0,0,1,0,0,0,1,0,12,0,0,0
0,0,0,1,11,0,0,1,12,0,12,0,0
0,0,0,1,0,6,5,1,0,12,0,0,0
0,0,0,0,1,1,1,0,0,0,0,0,0
0,0,0,0,0,0,0,0,0,0,0,0,0
0,0,0,0,0,0,0,0,0,0,0,0,0
0,0,0,0,0,0,0,0,0,0,0,0,0
endlayer

layer
0,0,0,0,0,0,0,0,0,0,0,0,0
0,0,0,0,0,0,0,0,0,0,0,0,0
0,0,0,0,0,0,0,0,0,0,0,0,0
0,0,0,0,0,0,0,0,0,0,0,0,0
0,0,0,0,1,1,1,0,0,0,0,0,0
0,0,0,1,0,0,0,1,0,0,0,0,0
0,0,0,1,0,0,0,1,0,12,0,0,0
0,0,0,1,5,0,0,1,0,0,0,0,0
0,0,0,0,1,1,1,0,0,0,0,0,0
0,0,0,0,0,0,0,0,0,0,0,0,0
0,0,0,0,0,0,0,0,0,0,0,0,0
0,0,0,0,0,0,0,0,0,0,0,0,0
endlayer

layer
0,0,0,0,0,0,0,0,0,0,0,0,0
0,0,0,0,0,0,0,0,0,0,0,0,0
0,0,0,0,0,0,0,0,0,0,0,0,0
0,0,0,0,1,1,1,0,0,0,0,0,0
0,0,0,1,3,3,3,1,0,0,0,0,0
0,0,1,3,3,3,3,3,1,0,0,0,0
0,0,1,5,3,3,6,3,1,12,0,0,0
0,0,1,13,0,0,0,3,1,0,0,0,0
0,0,0,1,3,3,3,1,0,0,0,0,0
0,0,0,0,1,1,1,0,0,0,0,0,0
0,0,0,0,0,0,0,0,0,0,0,0,0
0,0,0,0,0,0,0,0,0,0,0,0,0
endlayer

layer
0,0,0,0,0,0,0,0,0,0,0,0,0
0,0,0,0,0,0,0,0,0,0,0,0,0
0,0,0,0,0,0,0,0,0,0,0,0,0
0,0,0,0,1,1,1,0,0,0,0,0,0
0,0,0,1,0,0,0,1,0,0,0,0,0
0,0,1,0,0,15,0,14,1,0,0,0,0
0,0,1,0,0,16,0,14,1,0,0,0,0
0,0,1,0,0,0,0,14,1,0,0,0,0
0,0,0,1,14,14,14,1,0,0,0,0,0
0,0,0,0,1,1,1,0,0,0,0,0,0
0,0,0,0,0,0,0,0,0,0,0,0,0
0,0,0,0,0,0,0,0,0,0,0,0,0
endlayer

layer
0,0,0,0,0,0,0,0,0,0,0,0,0
0,0,0,0,0,0,0,0,0,0,0,0,0
0,0,0,0,0,0,0,0,0,0,0,0,0
0,0,0,0,1,10,1,0,0,0,0,0,0
0,0,0,1,11,0,9,1,0,0,0,0,0
0,0,1,0,0,0,0,14,1,0,0,0,0
0,0,10,0,0,0,0,14,1,0,0,0,0
0,0,1,0,0,0,0,14,1,0,0,0,0
0,0,0,1,7,0,9,1,0,0,0,0,0
0,0,0,0,1,10,1,0,0,0,0,0,0
0,0,0,0,0,0,0,0,0,0,0,0,0
0,0,0,0,0,0,0,0,0,0,0,0,0
endlayer

layer
0,0,0,0,0,0,0,0,0,0,0,0,0
0,0,0,0,0,0,0,0,0,0,0,0,0
0,0,0,0,12,12,12,0,0,0,0,0,0
0,0,0,12,1,1,1,12,0,0,0,0,0
0,0,12,1,0,0,0,1,12,0,0,0,0
0,12,1,0,0,0,0,14,1,12,0,0,0
0,12,1,0,0,0,0,14,1,12,0,0,0
0,12,1,0,0,0,0,14,1,12,0,0,0
0,0,12,1,0,0,0,1,12,0,0,0,0
0,0,0,12,1,1,1,12,0,0,0,0,0
0,0,0,0,12,12,12,0,0,0,0,0,0
0,0,0,0,0,0,0,0,0,0,0,0,0
endlayer

layer
0,0,0,0,0,0,0,0,0,0,0,0,0
0,0,0,0,0,0,0,0,0,0,0,0,0
0,0,0,0,0,0,0,0,0,0,0,0,0
0,0,0,0,12,12,12,0,0,0,0,0,0
0,0,0,12,0,0,0,12,0,0,0,0,0
0,0,12,0,0,0,0,0,12,0,0,0,0
0,0,12,0,0,0,0,0,12,0,0,0,0
0,0,12,0,0,0,0,0,12,0,0,0,0
0,0,0,12,0,0,0,12,0,0,0,0,0
0,0,0,0,12,12,12,0,0,0,0,0,0
0,0,0,0,0,0,0,0,0,0,0,0,0
0,0,0,0,0,0,0,0,0,0,0,0,0
endlayer

layer
0,0,0,0,0,0,0,0,0,0,0,0,0
0,0,0,0,0,0,0,0,0,0,0,0,0
0,0,0,0,0,0,0,0,0,0,0,0,0
0,0,0,0,0,0,0,0,0,0,0,0,0
0,0,0,0,12,12,12,0,0,0,0,0,0
0,0,0,12,0,0,0,12,0,0,0,0,0
0,0,0,12,0,0,0,12,0,0,0,0,0
0,0,0,12,0,0,0,12,0,0,0,0,0
0,0,0,0,12,12,12,0,0,0,0,0,0
0,0,0,0,0,0,0,0,0,0,0,0,0
0,0,0,0,0,0,0,0,0,0,0,0,0
0,0,0,0,0,0,0,0,0,0,0,0,0
endlayer

layer
0,0,0,0,0,0,0,0,0,0,0,0,0
0,0,0,0,0,0,0,0,0,0,0,0,0
0,0,0,0,0,0,0,0,0,0,0,0,0
0,0,0,0,0,0,0,0,0,0,0,0,0
0,0,0,0,0,12,0,0,0,0,0,0,0
0,0,0,0,12,0,12,0,0,0,0,0,0
0,0,0,12,0,0,0,12,0,0,0,0,0
0,0,0,0,12,0,12,0,0,0,0,0,0
0,0,0,0,0,12,0,0,0,0,0,0,0
0,0,0,0,0,0,0,0,0,0,0,0,0
0,0,0,0,0,0,0,0,0,0,0,0,0
0,0,0,0,0,0,0,0,0,0,0,0,0
endlayer

layer
0,0,0,0,0,0,0,0,0,0,0,0,0
0,0,0,0,0,0,0,0,0,0,0,0,0
0,0,0,0,0,0,0,0,0,0,0,0,0
0,0,0,0,0,0,0,0,0,0,0,0,0
0,0,0,0,0,0,0,0,0,0,0,0,0
0,0,0,0,12,12,12,0,0,0,0,0,0
0,0,0,0,12,0,12,0,0,0,0,0,0
0,0,0,0,12,12,12,0,0,0,0,0,0
0,0,0,0,0,0,0,0,0,0,0,0,0
0,0,0,0,0,0,0,0,0,0,0,0,0
0,0,0,0,0,0,0,0,0,0,0,0,0
0,0,0,0,0,0,0,0,0,0,0,0,0
endlayer

layer
0,0,0,0,0,0,0,0,0,0,0,0,0
0,0,0,0,0,0,0,0,0,0,0,0,0
0,0,0,0,0,0,0,0,0,0,0,0,0
0,0,0,0,0,0,0,0,0,0,0,0,0
0,0,0,0,0,0,0,0,0,0,0,0,0
0,0,0,0,0,12,0,0,0,0,0,0,0
0,0,0,0,12,0,12,0,0,0,0,0,0
0,0,0,0,0,12,0,0,0,0,0,0,0
0,0,0,0,0,0,0,0,0,0,0,0,0
0,0,0,0,0,0,0,0,0,0,0,0,0
0,0,0,0,0,0,0,0,0,0,0,0,0
0,0,0,0,0,0,0,0,0,0,0,0,0
endlayer

layer
0,0,0,0,0,0,0,0,0,0,0,0,0
0,0,0,0,0,0,0,0,0,0,0,0,0
0,0,0,0,0,0,0,0,0,0,0,0,0
0,0,0,0,0,0,0,0,0,0,0,0,0
0,0,0,0,0,0,0,0,0,0,0,0,0
0,0,0,0,0,0,0,0,0,0,0,0,0
0,0,0,0,0,12,0,0,0,0,0,0,0
0,0,0,0,0,0,0,0,0,0,0,0,0
0,0,0,0,0,0,0,0,0,0,0,0,0
0,0,0,0,0,0,0,0,0,0,0,0,0
0,0,0,0,0,0,0,0,0,0,0,0,0
0,0,0,0,0,0,0,0,0,0,0,0,0
endlayer

layer
0,0,0,0,0,0,0,0,0,0,0,0,0
0,0,0,0,0,0,0,0,0,0,0,0,0
0,0,0,0,0,0,0,0,0,0,0,0,0
0,0,0,0,0,0,0,0,0,0,0,0,0
0,0,0,0,0,0,0,0,0,0,0,0,0
0,0,0,0,0,0,0,0,0,0,0,0,0
0,0,0,0,0,12,0,0,0,0,0,0,0
0,0,0,0,0,0,0,0,0,0,0,0,0
0,0,0,0,0,0,0,0,0,0,0,0,0
0,0,0,0,0,0,0,0,0,0,0,0,0
0,0,0,0,0,0,0,0,0,0,0,0,0
0,0,0,0,0,0,0,0,0,0,0,0,0
endlayer

